<?xml version="1.0" ?>
<!-- =================================================================================== -->
<!-- |    This document was autogenerated by xacro from /val_controller_ws/src/val_description/model/robots/forearm_left.xacro | -->
<!-- |    EDITING THIS FILE BY HAND IS NOT RECOMMENDED                                 | -->
<!-- =================================================================================== -->
<robot name="valkyrie">
  <!--roll-->
  <link name="world"/>
  <link name="leftForearmLink">
    <inertial>
      <mass value="2.476"/>
      <origin rpy="0 0 0" xyz="0.015000 -0.13 0.019564"/>
      <inertia ixx="0.01175543" ixy="-0.001300853" ixz="-0.000727141" iyy="0.005071567" iyz="-0.001695416" izz="0.011365657"/>
    </inertial>
    <visual>
      <geometry>
        <mesh filename="package://val_description/model/meshes/arms/aj5_left.dae"/>
      </geometry>
      <origin rpy="0.0 0.0 0.0" xyz="0.0 0.0 0.0"/>
    </visual>
    <collision>
      <geometry>
        <mesh filename="package://val_description/model/meshes/arms/aj5_left.dae"/>
      </geometry>
      <origin rpy="0 0 0" xyz="0 0 0"/>
    </collision>
  </link>
  <link name="leftWristRollLink">
    <inertial>
      <mass value="0.14"/>
      <origin rpy="0 0 0" xyz="0 0 0"/>
      <inertia ixx="3.0251e-05" ixy="-1.25e-07" ixz="-3.6e-08" iyy="3.772e-05" iyz="0.0" izz="9.395e-06"/>
    </inertial>
    <visual>
      <geometry>
        <mesh filename="package://val_description/model/meshes/arms/aj6_left.dae"/>
      </geometry>
      <origin rpy="0.0 0.0 0.0" xyz="0.0 0.0 0.0"/>
    </visual>
    <collision>
      <geometry>
        <mesh filename="package://val_description/model/meshes/arms/aj6_left.dae"/>
      </geometry>
      <origin rpy="0 0 0" xyz="0 0 0"/>
    </collision>
  </link>
  <link name="leftPalm">
    <inertial>
      <mass value="0.712"/>
      <origin rpy="0 0 0" xyz="0.002954 -0.052034 -0.000236"/>
      <inertia ixx="0.000943493" ixy="3.4393e-05" ixz="-3.8828e-05" iyy="0.000711024" iyz="2.3429e-05" izz="0.000610199"/>
    </inertial>
    <visual>
      <geometry>
        <mesh filename="package://val_description/model/meshes/arms/palm_left.dae"/>
      </geometry>
      <origin rpy="0.0 0.0 0.0" xyz="0.0 0.0 0.0"/>
    </visual>
    <collision>
      <geometry>
        <mesh filename="package://val_description/model/meshes/arms/palm_left.dae"/>
      </geometry>
      <origin rpy="0 0 0" xyz="0 0 0"/>
    </collision>
  </link>
  <gazebo reference="leftPalm">
    <kp>1e5</kp>
    <kd>1</kd>
    <maxVel>0.1</maxVel>
    <minDepth>0.0015</minDepth>
  </gazebo>
  <joint name="leftForearmYaw" type="revolute">
    <origin rpy="0.0 0.0 0.0" xyz="-0.0254 0 0"/>
    <axis xyz="0 1 0"/>
    <parent link="world"/>
    <child link="leftForearmLink"/>
    <limit effort="26" lower="-2.019" upper="3.14" velocity="5"/>
    <controller_gains Kd="0.0" Ki="0.0" Kp="1000"/>
    <dynamics damping="0.1" friction="0.0"/>
  </joint>
  <gazebo reference="leftForearmYaw">
    <provideFeedback>1</provideFeedback>
    <implicitSpringDamper>1</implicitSpringDamper>
  </gazebo>
  <joint name="leftWristRoll" type="revolute">
    <origin rpy="0.0 0.0 0.0" xyz="0.0 -0.2871 0.0"/>
    <axis xyz="1 0 0"/>
    <parent link="leftForearmLink"/>
    <child link="leftWristRollLink"/>
    <limit effort="14" lower="-0.35" upper="0.35" velocity="1"/>
    <controller_gains Kd="0" Ki="0.0" Kp="500"/>
    <dynamics damping="0.1" friction="0.0"/>
  </joint>
  <gazebo reference="leftWristRoll">
    <provideFeedback>1</provideFeedback>
    <implicitSpringDamper>1</implicitSpringDamper>
  </gazebo>
  <joint name="leftWristPitch" type="revolute">
    <origin rpy="0.0 0.0 0.0" xyz="0.0 0.0 0.0"/>
    <axis xyz="0 0 1"/>
    <parent link="leftWristRollLink"/>
    <child link="leftPalm"/>
    <limit effort="14" lower="-0.6" upper="0.6" velocity="1"/>
    <controller_gains Kd="0" Ki="0.0" Kp="500"/>
    <dynamics damping="0.1" friction="0.0"/>
  </joint>
  <gazebo reference="leftWristPitch">
    <provideFeedback>1</provideFeedback>
    <implicitSpringDamper>1</implicitSpringDamper>
  </gazebo>
  <link name="leftThumbRollLink">
    <inertial>
      <mass value="0.017"/>
      <origin rpy="0 0 0" xyz="0 0 0.01"/>
      <inertia ixx="2.7778767e-06" ixy="5.6718533e-09" ixz="-9.5523207e-08" iyy="3.5462642e-06" iyz="3.663718e-08" izz="1.3553297e-06"/>
    </inertial>
    <visual>
      <geometry>
        <mesh filename="package://val_description/model/meshes/fingers/thumbj1_left.dae"/>
      </geometry>
      <origin rpy="0.0 0.0 0.0" xyz="0.0 0.0 0.0"/>
    </visual>
    <collision>
      <geometry>
        <mesh filename="package://val_description/model/meshes/fingers/thumbj1_left.dae"/>
      </geometry>
      <origin rpy="0 0 0" xyz="0 0 0"/>
    </collision>
  </link>
  <gazebo reference="leftThumbRollLink">
    <kp>1e5</kp>
    <kd>1</kd>
    <maxVel>0.1</maxVel>
    <minDepth>0.0015</minDepth>
  </gazebo>
  <link name="leftThumbPitch1Link">
    <inertial>
      <mass value="0.02"/>
      <origin rpy="0 0 0" xyz="0.0 -0.005 0.02"/>
      <inertia ixx="4.239e-06" ixy="0.0" ixz="-0.0" iyy="4.582e-06" iyz="0.0" izz="1.47e-06"/>
    </inertial>
    <visual>
      <geometry>
        <mesh filename="package://val_description/model/meshes/fingers/thumbj2_left.dae"/>
      </geometry>
      <origin rpy="0.0 0.0 0.0" xyz="0.0 0.0 0.0"/>
    </visual>
    <collision>
      <geometry>
        <mesh filename="package://val_description/model/meshes/fingers/thumbj2_left.dae"/>
      </geometry>
      <origin rpy="0 0 0" xyz="0 0 0"/>
    </collision>
  </link>
  <gazebo reference="leftThumbPitch1Link">
    <kp>1e5</kp>
    <kd>1</kd>
    <maxVel>0.1</maxVel>
    <minDepth>0.0015</minDepth>
  </gazebo>
  <link name="leftThumbPitch2Link">
    <inertial>
      <mass value="0.013"/>
      <origin rpy="0 0 0" xyz="0 -0.004 0.017"/>
      <inertia ixx="1.266e-06" ixy="0.0" ixz="-0.0" iyy="1.503e-06" iyz="-0.0" izz="6.99e-07"/>
    </inertial>
    <visual>
      <geometry>
        <mesh filename="package://val_description/model/meshes/fingers/thumbj3_left.dae"/>
      </geometry>
      <origin rpy="0.0 0.0 0.0" xyz="0.0 0.0 0.0"/>
    </visual>
    <collision>
      <geometry>
        <mesh filename="package://val_description/model/meshes/fingers/thumbj3_left.dae"/>
      </geometry>
      <origin rpy="0 0 0" xyz="0 0 0"/>
    </collision>
  </link>
  <gazebo reference="leftThumbPitch2Link">
    <kp>1e5</kp>
    <kd>1</kd>
    <maxVel>0.1</maxVel>
    <minDepth>0.0015</minDepth>
  </gazebo>
  <link name="leftThumbPitch3Link">
    <inertial>
      <mass value="0.006"/>
      <origin rpy="0 0 0" xyz="0 -0.004 0.01"/>
      <inertia ixx="3.22e-07" ixy="0.0" ixz="0.0" iyy="4.06e-07" iyz="0.0" izz="2.1e-07"/>
    </inertial>
    <visual>
      <geometry>
        <mesh filename="package://val_description/model/meshes/fingers/thumbj4_left.dae"/>
      </geometry>
      <origin rpy="0.0 0.0 0.0" xyz="0.0 0.0 0.0"/>
    </visual>
    <collision>
      <geometry>
        <mesh filename="package://val_description/model/meshes/fingers/thumbj4_left.dae"/>
      </geometry>
      <origin rpy="0 0 0" xyz="0 0 0"/>
    </collision>
  </link>
  <gazebo reference="leftThumbPitch3Link">
    <kp>1e5</kp>
    <kd>1</kd>
    <maxVel>0.1</maxVel>
    <minDepth>0.0015</minDepth>
  </gazebo>
  <joint name="leftThumbRoll" type="revolute">
    <origin rpy="0.3491 0.0 0.0" xyz="0.0049 -0.0351 0.0228"/>
    <axis xyz="0 1 0"/>
    <parent link="leftPalm"/>
    <child link="leftThumbRollLink"/>
    <limit effort="10" lower="0.0" upper="2.356" velocity="1"/>
    <controller_gains Kd="0.0" Ki="0.0" Kp="5.0"/>
    <dynamics damping="0.5" friction="0.5"/>
  </joint>
  <gazebo reference="leftThumbRoll">
    <provideFeedback>1</provideFeedback>
    <implicitSpringDamper>1</implicitSpringDamper>
  </gazebo>
  <joint name="leftThumbPitch1" type="revolute">
    <origin rpy="-0.3491 0.0 0.0" xyz="0.0 0.0 0.0229"/>
    <axis xyz="1 0 0"/>
    <parent link="leftThumbRollLink"/>
    <child link="leftThumbPitch1Link"/>
    <limit effort="10" lower="0.0" upper="1.658" velocity="1"/>
    <controller_gains Kd="0.0" Ki="0.0" Kp="5.0"/>
    <dynamics damping="0.5" friction="0.5"/>
  </joint>
  <gazebo reference="leftThumbPitch1">
    <provideFeedback>1</provideFeedback>
    <implicitSpringDamper>1</implicitSpringDamper>
  </gazebo>
  <joint name="leftThumbPitch2" type="revolute">
    <origin rpy="0.0 0.0 0.0" xyz="0.0 -0.0066 0.0375"/>
    <axis xyz="1 0 0"/>
    <parent link="leftThumbPitch1Link"/>
    <child link="leftThumbPitch2Link"/>
    <limit effort="10" lower="0.0" upper="1.92" velocity="1"/>
    <controller_gains Kd="0.0" Ki="0.0" Kp="5.0"/>
    <mimic joint="leftThumbPitch1" multiplier="0.835" offset="0"/>
    <dynamics damping="0.5" friction="0.5"/>
  </joint>
  <gazebo reference="leftThumbPitch2">
    <provideFeedback>1</provideFeedback>
    <implicitSpringDamper>1</implicitSpringDamper>
  </gazebo>
  <joint name="leftThumbPitch3" type="revolute">
    <origin rpy="0.0 0.0 0.0" xyz="0.0 -0.0049 0.0275"/>
    <axis xyz="1 0 0"/>
    <parent link="leftThumbPitch2Link"/>
    <child link="leftThumbPitch3Link"/>
    <limit effort="10" lower="0.0" upper="1.57" velocity="1"/>
    <controller_gains Kd="0.0" Ki="0.0" Kp="5.0"/>
    <mimic joint="leftThumbPitch1" multiplier="0.668" offset="0"/>
    <dynamics damping="0.5" friction="0.5"/>
  </joint>
  <gazebo reference="leftThumbPitch3">
    <provideFeedback>1</provideFeedback>
    <implicitSpringDamper>1</implicitSpringDamper>
  </gazebo>
  <link name="leftIndexFingerPitch1Link">
    <inertial>
      <mass value="0.02"/>
      <origin rpy="0 0 0" xyz="0 -0.02 0"/>
      <inertia ixx="4.232e-06" ixy="-6e-08" ixz="-8e-09" iyy="1.215e-06" iyz="-7e-09" izz="3.892e-06"/>
    </inertial>
    <visual>
      <geometry>
        <mesh filename="package://val_description/model/meshes/fingers/indexj1_left.dae"/>
      </geometry>
      <origin rpy="0.0 0.0 0.0" xyz="0.0 0.0 0.0"/>
    </visual>
    <collision>
      <geometry>
        <mesh filename="package://val_description/model/meshes/fingers/indexj1_left.dae"/>
      </geometry>
      <origin rpy="0 0 0" xyz="0 0 0"/>
    </collision>
  </link>
  <gazebo reference="leftIndexFingerPitch1Link">
    <kp>1e5</kp>
    <kd>1</kd>
    <maxVel>0.1</maxVel>
    <minDepth>0.0015</minDepth>
  </gazebo>
  <link name="leftIndexFingerPitch2Link">
    <inertial>
      <mass value="0.018"/>
      <origin rpy="0 0 0" xyz="0 -0.013 0"/>
      <inertia ixx="1.562e-06" ixy="-1.7e-08" ixz="-1.3e-08" iyy="7.22e-07" iyz="3.1e-08" izz="1.255e-06"/>
    </inertial>
    <visual>
      <geometry>
        <mesh filename="package://val_description/model/meshes/fingers/indexj2_left.dae"/>
      </geometry>
      <origin rpy="0.0 0.0 0.0" xyz="0.0 0.0 0.0"/>
    </visual>
    <collision>
      <geometry>
        <mesh filename="package://val_description/model/meshes/fingers/indexj2_left.dae"/>
      </geometry>
      <origin rpy="0 0 0" xyz="0 0 0"/>
    </collision>
  </link>
  <gazebo reference="leftIndexFingerPitch2Link">
    <kp>1e5</kp>
    <kd>1</kd>
    <maxVel>0.1</maxVel>
    <minDepth>0.0015</minDepth>
  </gazebo>
  <link name="leftIndexFingerPitch3Link">
    <inertial>
      <mass value="0.01"/>
      <origin rpy="0 0 0" xyz="0 -0.01 0"/>
      <inertia ixx="6.02e-07" ixy="-2.4e-08" ixz="0.0" iyy="2.09e-07" iyz="1.7e-08" izz="5.02e-07"/>
    </inertial>
    <visual>
      <geometry>
        <mesh filename="package://val_description/model/meshes/fingers/indexj3_left.dae"/>
      </geometry>
      <origin rpy="0.0 0.0 0.0" xyz="0.0 0.0 0.0"/>
    </visual>
    <collision>
      <geometry>
        <mesh filename="package://val_description/model/meshes/fingers/indexj3_left.dae"/>
      </geometry>
      <origin rpy="0 0 0" xyz="0 0 0"/>
    </collision>
  </link>
  <gazebo reference="leftIndexFingerPitch3Link">
    <kp>1e5</kp>
    <kd>1</kd>
    <maxVel>0.1</maxVel>
    <minDepth>0.0015</minDepth>
  </gazebo>
  <joint name="leftIndexFingerPitch1" type="revolute">
    <origin rpy="0.02 0.0 0.0" xyz="0.0022 -0.0976 0.017"/>
    <axis xyz="0 0 1"/>
    <parent link="leftPalm"/>
    <child link="leftIndexFingerPitch1Link"/>
    <limit effort="10" lower="0.0" upper="1.57" velocity="1"/>
    <controller_gains Kd="0.0" Ki="0.0" Kp="5.0"/>
    <dynamics damping="0.5" friction="0.5"/>
  </joint>
  <gazebo reference="leftIndexFingerPitch1">
    <provideFeedback>1</provideFeedback>
    <implicitSpringDamper>1</implicitSpringDamper>
  </gazebo>
  <joint name="leftIndexFingerPitch2" type="revolute">
    <origin rpy="0.0 0.0 0.0" xyz="0.0 -0.0381 0.0"/>
    <axis xyz="0 0 1"/>
    <parent link="leftIndexFingerPitch1Link"/>
    <child link="leftIndexFingerPitch2Link"/>
    <limit effort="10" lower="0.0" upper="1.658" velocity="1"/>
    <controller_gains Kd="0.0" Ki="0.0" Kp="5.0"/>
    <mimic joint="leftIndexFingerPitch1" multiplier="0.835" offset="0"/>
    <dynamics damping="0.5" friction="0.5"/>
  </joint>
  <gazebo reference="leftIndexFingerPitch2">
    <provideFeedback>1</provideFeedback>
    <implicitSpringDamper>1</implicitSpringDamper>
  </gazebo>
  <joint name="leftIndexFingerPitch3" type="revolute">
    <origin rpy="0.0 0.0 0.0" xyz="0.0 -0.0229 0"/>
    <axis xyz="0 0 1"/>
    <parent link="leftIndexFingerPitch2Link"/>
    <child link="leftIndexFingerPitch3Link"/>
    <limit effort="10" lower="0.0" upper="1.92" velocity="1"/>
    <controller_gains Kd="0.0" Ki="0.0" Kp="5.0"/>
    <mimic joint="leftIndexFingerPitch1" multiplier="0.668" offset="0"/>
    <dynamics damping="0.5" friction="0.5"/>
  </joint>
  <gazebo reference="leftIndexFingerPitch3">
    <provideFeedback>1</provideFeedback>
    <implicitSpringDamper>1</implicitSpringDamper>
  </gazebo>
  <link name="leftMiddleFingerPitch1Link">
    <inertial>
      <mass value="0.02"/>
      <origin rpy="0 0 0" xyz="0 -0.02 0"/>
      <inertia ixx="5.148e-06" ixy="-4.2e-08" ixz="-1.1e-08" iyy="1.322e-06" iyz="-4e-09" izz="4.592e-06"/>
    </inertial>
    <visual>
      <geometry>
        <mesh filename="package://val_description/model/meshes/fingers/middlej1_left.dae"/>
      </geometry>
      <origin rpy="0.0 0.0 0.0" xyz="0.0 0.0 0.0"/>
    </visual>
    <collision>
      <geometry>
        <mesh filename="package://val_description/model/meshes/fingers/middlej1_left.dae"/>
      </geometry>
      <origin rpy="0 0 0" xyz="0 0 0"/>
    </collision>
  </link>
  <gazebo reference="leftMiddleFingerPitch1Link">
    <kp>1e5</kp>
    <kd>1</kd>
    <maxVel>0.1</maxVel>
    <minDepth>0.0015</minDepth>
  </gazebo>
  <link name="leftMiddleFingerPitch2Link">
    <inertial>
      <mass value="0.011"/>
      <origin rpy="0 0 0" xyz="0 -0.013 0"/>
      <inertia ixx="1.97e-06" ixy="3.4e-08" ixz="-1.1e-08" iyy="5.54e-07" iyz="-7.8e-08" izz="2.272e-06"/>
    </inertial>
    <visual>
      <geometry>
        <mesh filename="package://val_description/model/meshes/fingers/middlej2_left.dae"/>
      </geometry>
      <origin rpy="0.0 0.0 0.0" xyz="0.0 0.0 0.0"/>
    </visual>
    <collision>
      <geometry>
        <mesh filename="package://val_description/model/meshes/fingers/middlej2_left.dae"/>
      </geometry>
      <origin rpy="0 0 0" xyz="0 0 0"/>
    </collision>
  </link>
  <gazebo reference="leftMiddleFingerPitch2Link">
    <kp>1e5</kp>
    <kd>1</kd>
    <maxVel>0.1</maxVel>
    <minDepth>0.0015</minDepth>
  </gazebo>
  <link name="leftMiddleFingerPitch3Link">
    <inertial>
      <mass value="0.006"/>
      <origin rpy="0 0 0" xyz="0 -0.01 0"/>
      <inertia ixx="3.96e-07" ixy="-9e-09" ixz="-1e-09" iyy="1.6e-07" iyz="1.6e-08" izz="3.03e-07"/>
    </inertial>
    <visual>
      <geometry>
        <mesh filename="package://val_description/model/meshes/fingers/middlej3_left.dae"/>
      </geometry>
      <origin rpy="0.0 0.0 0.0" xyz="0.0 0.0 0.0"/>
    </visual>
    <collision>
      <geometry>
        <mesh filename="package://val_description/model/meshes/fingers/middlej3_left.dae"/>
      </geometry>
      <origin rpy="0 0 0" xyz="0 0 0"/>
    </collision>
  </link>
  <gazebo reference="leftMiddleFingerPitch3Link">
    <kp>1e5</kp>
    <kd>1</kd>
    <maxVel>0.1</maxVel>
    <minDepth>0.0015</minDepth>
  </gazebo>
  <joint name="leftMiddleFingerPitch1" type="revolute">
    <origin rpy="0.1222 0.0 0.0" xyz="0.0022 -0.097 -0.0119"/>
    <axis xyz="0 0 1"/>
    <parent link="leftPalm"/>
    <child link="leftMiddleFingerPitch1Link"/>
    <limit effort="10" lower="0.0" upper="1.658" velocity="1"/>
    <controller_gains Kd="0.0" Ki="0.0" Kp="5.0"/>
    <dynamics damping="0.5" friction="0.5"/>
  </joint>
  <gazebo reference="leftMiddleFingerPitch1">
    <provideFeedback>1</provideFeedback>
    <implicitSpringDamper>1</implicitSpringDamper>
  </gazebo>
  <joint name="leftMiddleFingerPitch2" type="revolute">
    <origin rpy="0.0 0.0 0.0" xyz="0.0 -0.0381 0.0"/>
    <axis xyz="0 0 1"/>
    <parent link="leftMiddleFingerPitch1Link"/>
    <child link="leftMiddleFingerPitch2Link"/>
    <limit effort="10" lower="0.0" upper="1.92" velocity="1"/>
    <controller_gains Kd="0.0" Ki="0.0" Kp="5.0"/>
    <mimic joint="leftMiddleFingerPitch1" multiplier="0.835" offset="0"/>
    <dynamics damping="0.5" friction="0.5"/>
  </joint>
  <gazebo reference="leftMiddleFingerPitch2">
    <provideFeedback>1</provideFeedback>
    <implicitSpringDamper>1</implicitSpringDamper>
  </gazebo>
  <joint name="leftMiddleFingerPitch3" type="revolute">
    <origin rpy="0.0 0.0 0.0" xyz="0.0 -0.0229 0.0"/>
    <axis xyz="0 0 1"/>
    <parent link="leftMiddleFingerPitch2Link"/>
    <child link="leftMiddleFingerPitch3Link"/>
    <limit effort="10" lower="0.0" upper="1.57" velocity="1"/>
    <controller_gains Kd="0.0" Ki="0.0" Kp="5.0"/>
    <mimic joint="leftMiddleFingerPitch1" multiplier="0.668" offset="0"/>
    <dynamics damping="0.5" friction="0.5"/>
  </joint>
  <gazebo reference="leftMiddleFingerPitch3">
    <provideFeedback>1</provideFeedback>
    <implicitSpringDamper>1</implicitSpringDamper>
  </gazebo>
  <link name="leftPinkyPitch1Link">
    <inertial>
      <mass value="0.02"/>
      <origin rpy="0 0 0" xyz="0 -0.02 0"/>
      <inertia ixx="5.148e-06" ixy="-4.2e-08" ixz="-1.1e-08" iyy="1.322e-06" iyz="-4e-09" izz="4.592e-06"/>
    </inertial>
    <visual>
      <geometry>
        <mesh filename="package://val_description/model/meshes/fingers/pinkyj1_left.dae"/>
      </geometry>
      <origin rpy="0.0 0.0 0.0" xyz="0.0 0.0 0.0"/>
    </visual>
    <collision>
      <geometry>
        <mesh filename="package://val_description/model/meshes/fingers/pinkyj1_left.dae"/>
      </geometry>
      <origin rpy="0 0 0" xyz="0 0 0"/>
    </collision>
  </link>
  <gazebo reference="leftPinkyPitch1Link">
    <kp>1e5</kp>
    <kd>1</kd>
    <maxVel>0.1</maxVel>
    <minDepth>0.0015</minDepth>
  </gazebo>
  <link name="leftPinkyPitch2Link">
    <inertial>
      <mass value="0.011"/>
      <origin rpy="0 0 0" xyz="0 -0.013 0"/>
      <inertia ixx="1.97e-06" ixy="3.4e-08" ixz="-1.1e-08" iyy="5.54e-07" iyz="-7.8e-08" izz="2.272e-06"/>
    </inertial>
    <visual>
      <geometry>
        <mesh filename="package://val_description/model/meshes/fingers/pinkyj2_left.dae"/>
      </geometry>
      <origin rpy="0.0 0.0 0.0" xyz="0.0 0.0 0.0"/>
    </visual>
    <collision>
      <geometry>
        <mesh filename="package://val_description/model/meshes/fingers/pinkyj2_left.dae"/>
      </geometry>
      <origin rpy="0 0 0" xyz="0 0 0"/>
    </collision>
  </link>
  <gazebo reference="leftPinkyPitch2Link">
    <kp>1e5</kp>
    <kd>1</kd>
    <maxVel>0.1</maxVel>
    <minDepth>0.0015</minDepth>
  </gazebo>
  <link name="leftPinkyPitch3Link">
    <inertial>
      <mass value="0.006"/>
      <origin rpy="0 0 0" xyz="0 -0.01 0"/>
      <inertia ixx="3.96e-07" ixy="-9e-09" ixz="-1e-09" iyy="1.6e-07" iyz="1.6e-08" izz="3.03e-07"/>
    </inertial>
    <visual>
      <geometry>
        <mesh filename="package://val_description/model/meshes/fingers/pinkyj3_left.dae"/>
      </geometry>
      <origin rpy="0.0 0.0 0.0" xyz="0.0 0.0 0.0"/>
    </visual>
    <collision>
      <geometry>
        <mesh filename="package://val_description/model/meshes/fingers/pinkyj3_left.dae"/>
      </geometry>
      <origin rpy="0 0 0" xyz="0 0 0"/>
    </collision>
  </link>
  <gazebo reference="leftPinkyPitch3Link">
    <kp>1e5</kp>
    <kd>1</kd>
    <maxVel>0.1</maxVel>
    <minDepth>0.0015</minDepth>
  </gazebo>
  <joint name="leftPinkyPitch1" type="revolute">
    <origin rpy="0.22 0.0 0.0" xyz="0.0022 -0.0838 -0.041"/>
    <axis xyz="0 0 1"/>
    <parent link="leftPalm"/>
    <child link="leftPinkyPitch1Link"/>
    <limit effort="10" lower="0.0" upper="1.57" velocity="1"/>
    <controller_gains Kd="0.0" Ki="0.0" Kp="5.0"/>
    <dynamics damping="0.5" friction="0.5"/>
  </joint>
  <gazebo reference="leftPinkyPitch1">
    <provideFeedback>1</provideFeedback>
    <implicitSpringDamper>1</implicitSpringDamper>
  </gazebo>
  <joint name="leftPinkyPitch2" type="revolute">
    <origin rpy="0.0 0.0 0.0" xyz="0.0 -0.0381 0.0"/>
    <axis xyz="0 0 1"/>
    <parent link="leftPinkyPitch1Link"/>
    <child link="leftPinkyPitch2Link"/>
    <limit effort="10" lower="0.0" upper="1.658" velocity="1"/>
    <controller_gains Kd="0.0" Ki="0.0" Kp="5.0"/>
    <mimic joint="leftPinkyPitch1" multiplier="0.835" offset="0"/>
    <dynamics damping="0.5" friction="0.5"/>
  </joint>
  <gazebo reference="leftPinkyPitch2">
    <provideFeedback>1</provideFeedback>
    <implicitSpringDamper>1</implicitSpringDamper>
  </gazebo>
  <joint name="leftPinkyPitch3" type="revolute">
    <origin rpy="0.0 0.0 0.0" xyz="0.0 -0.0229 0.0"/>
    <axis xyz="0 0 1"/>
    <parent link="leftPinkyPitch2Link"/>
    <child link="leftPinkyPitch3Link"/>
    <limit effort="10" lower="0.0" upper="1.92" velocity="1"/>
    <controller_gains Kd="0.0" Ki="0.0" Kp="5.0"/>
    <mimic joint="leftPinkyPitch1" multiplier="0.668" offset="0"/>
    <dynamics damping="0.5" friction="0.5"/>
  </joint>
  <gazebo reference="leftPinkyPitch3">
    <provideFeedback>1</provideFeedback>
    <implicitSpringDamper>1</implicitSpringDamper>
  </gazebo>
  <transmission name="leftForearmYawTransmission">
    <type>transmission_interface/SimpleTransmission</type>
    <joint name="leftForearmYaw">
      <hardwareInterface>EffortJointInterface</hardwareInterface>
    </joint>
    <actuator name="leftForearmYaw">
      <node name="/left_arm/j5"/>
      <mechanicalReduction>1</mechanicalReduction>
      <api name="robot_hardware_interface/TurbodriverAPI"/>
    </actuator>
  </transmission>
  <transmission name="leftIndexFingerMotorPitch1Transmission">
    <type>transmission_interface/SimpleTransmission</type>
    <joint name="leftIndexFingerMotorPitch1">
      <hardwareInterface>EffortJointInterface</hardwareInterface>
    </joint>
    <actuator name="leftIndexFingerMotorPitch1">
      <node name="/left_arm/hand/index"/>
      <mechanicalReduction>1</mechanicalReduction>
      <api name="robot_hardware_interface/TurbodriverAPI"/>
    </actuator>
  </transmission>
  <transmission name="leftMiddleFingerMotorPitch1Transmission">
    <type>transmission_interface/SimpleTransmission</type>
    <joint name="leftMiddleFingerMotorPitch1">
      <hardwareInterface>EffortJointInterface</hardwareInterface>
    </joint>
    <actuator name="leftMiddleFingerMotorPitch1">
      <node name="/left_arm/hand/middle"/>
      <mechanicalReduction>1</mechanicalReduction>
      <api name="robot_hardware_interface/TurbodriverAPI"/>
    </actuator>
  </transmission>
  <transmission name="leftPinkyMotorPitch1Transmission">
    <type>transmission_interface/SimpleTransmission</type>
    <joint name="leftPinkyMotorPitch1">
      <hardwareInterface>EffortJointInterface</hardwareInterface>
    </joint>
    <actuator name="leftPinkyMotorPitch1">
      <node name="/left_arm/hand/pinky"/>
      <mechanicalReduction>1</mechanicalReduction>
      <api name="robot_hardware_interface/TurbodriverAPI"/>
    </actuator>
  </transmission>
  <transmission name="leftThumbMotorRollTransmission">
    <type>transmission_interface/SimpleTransmission</type>
    <joint name="leftThumbMotorRoll">
      <hardwareInterface>EffortJointInterface</hardwareInterface>
    </joint>
    <actuator name="leftThumbMotorRoll">
      <node name="/left_arm/hand/thumb_roll"/>
      <mechanicalReduction>1</mechanicalReduction>
      <api name="robot_hardware_interface/TurbodriverAPI"/>
    </actuator>
  </transmission>
  <transmission name="leftThumbMotorPitch1Transmission">
    <type>transmission_interface/SimpleTransmission</type>
    <joint name="leftThumbMotorPitch1">
      <hardwareInterface>EffortJointInterface</hardwareInterface>
    </joint>
    <actuator name="leftThumbMotorPitch1">
      <node name="/left_arm/hand/thumb_proximal"/>
      <mechanicalReduction>1</mechanicalReduction>
      <api name="robot_hardware_interface/TurbodriverAPI"/>
    </actuator>
  </transmission>
  <transmission name="leftThumbMotorPitch2Transmission">
    <type>transmission_interface/SimpleTransmission</type>
    <joint name="leftThumbMotorPitch2">
      <hardwareInterface>EffortJointInterface</hardwareInterface>
    </joint>
    <actuator name="leftThumbMotorPitch2">
      <node name="/left_arm/hand/thumb_distal"/>
      <mechanicalReduction>1</mechanicalReduction>
      <api name="robot_hardware_interface/TurbodriverAPI"/>
    </actuator>
  </transmission>
  <transmission name="leftWristTransmission">
    <type>robot_transmission_interface/WristPushrodTransmission</type>
    <joint name="leftWristPitch">
      <role>pitch</role>
      <hardwareInterface>EffortJointInterface</hardwareInterface>
    </joint>
    <joint name="leftWristRoll">
      <role>roll</role>
      <hardwareInterface>EffortJointInterface</hardwareInterface>
    </joint>
    <actuator name="leftWristRightActuator">
      <node name="/left_arm/wrist/right_actuator"/>
      <role>bottom</role>
      <mechanicalReduction>1</mechanicalReduction>
      <api name="robot_hardware_interface/TurbodriverAPI_linear_futek"/>
    </actuator>
    <actuator name="leftWristLeftActuator">
      <node name="/left_arm/wrist/left_actuator"/>
      <role>top</role>
      <mechanicalReduction>1</mechanicalReduction>
      <api name="robot_hardware_interface/TurbodriverAPI_linear_futek"/>
    </actuator>
  </transmission>
</robot>
