<?xml version="1.0" ?>
<!-- =================================================================================== -->
<!-- |    This document was autogenerated by xacro from /val_controller_ws/src/val_description/model/robots/leg_left.xacro | -->
<!-- |    EDITING THIS FILE BY HAND IS NOT RECOMMENDED                                 | -->
<!-- =================================================================================== -->
<robot name="ValkyrieA">
  <link name="world"/>
  <!--roll-->
  <link name="leftHipYawLink">
    <inertial>
      <mass value="2.39"/>
      <origin rpy="0 0 0" xyz="0.02176 -0.00131 0.03867"/>
      <inertia ixx="0.017260978" ixy="0.0" ixz="0.0" iyy="0.014866198" iyz="0.0" izz="0.011238178"/>
    </inertial>
    <visual>
      <geometry>
        <mesh filename="package://val_description/model/meshes/legs/lj1_left.dae"/>
      </geometry>
      <origin rpy="0.0 0.0 0.0" xyz="0.0 0.0 0.0"/>
    </visual>
    <collision>
      <geometry>
        <mesh filename="package://val_description/model/meshes/legs/lj1_left.dae"/>
      </geometry>
      <origin rpy="0 0 0" xyz="0 0 0"/>
    </collision>
  </link>
  <link name="leftHipRollLink">
    <inertial>
      <mass value="3.665"/>
      <origin rpy="0 0 0" xyz="0.012959 0.00755 -0.015950"/>
      <inertia ixx="0.005978962" ixy="-0.000234823" ixz="0.000553962" iyy="0.009372646" iyz="0.000778956" izz="0.008193117"/>
    </inertial>
  </link>
  <link name="leftHipPitchLink">
    <inertial>
      <mass value="10.2"/>
      <origin rpy="0 0 0" xyz="0.016691 0.091397 -0.207875"/>
      <inertia ixx="0.24083413" ixy="3.5915e-05" ixz="0.003699383" iyy="0.25689705" iyz="-0.001333005" izz="0.023276352"/>
    </inertial>
    <visual>
      <geometry>
        <mesh filename="package://val_description/model/meshes/legs/lj3_left.dae"/>
      </geometry>
      <origin rpy="0.0 0.0 0.0" xyz="0.0 0.0 0.0"/>
    </visual>
    <collision>
      <geometry>
        <mesh filename="package://val_description/model/meshes/legs/lj3_left.dae"/>
      </geometry>
      <origin rpy="0 0 0" xyz="0 0 0"/>
    </collision>
  </link>
  <link name="leftKneePitchLink">
    <inertial>
      <mass value="6.2"/>
      <origin rpy="0 0 0" xyz="-0.022183  0.001703  -0.189418"/>
      <inertia ixx="0.086935683" ixy="9.929e-05" ixz="0.000573207" iyy="0.091584066" iyz="0.000313745" izz="0.014017272"/>
    </inertial>
    <visual>
      <geometry>
        <mesh filename="package://val_description/model/meshes/legs/lj4_left.dae"/>
      </geometry>
      <origin rpy="0.0 0.0 0.0" xyz="0.0 0.0 0.0"/>
    </visual>
    <collision>
      <geometry>
        <mesh filename="package://val_description/model/meshes/legs/lj4_left.dae"/>
      </geometry>
      <origin rpy="0 0 0" xyz="0 0 0"/>
    </collision>
  </link>
  <link name="leftAnklePitchLink">
    <inertial>
      <mass value="0.03"/>
      <origin rpy="0 0 0" xyz="0.0 0.0 0.0"/>
      <inertia ixx="4.377e-06" ixy="0.0" ixz="0.0" iyy="4.322e-06" iyz="0.0" izz="7.015e-06"/>
    </inertial>
    <visual>
      <geometry>
        <mesh filename="package://val_description/model/meshes/legs/lj5.dae"/>
      </geometry>
      <origin rpy="0.0 0.0 0.0" xyz="0.0 0.0 0.0"/>
    </visual>
    <collision>
      <geometry>
        <mesh filename="package://val_description/model/meshes/legs/lj5.dae"/>
      </geometry>
      <origin rpy="0 0 0" xyz="0 0 0"/>
    </collision>
  </link>
  <link name="leftFoot">
    <inertial>
      <mass value="2.27"/>
      <origin rpy="0 0 0" xyz="0.037702  0.005161  -0.047634"/>
      <inertia ixx="0.00623936" ixy="0.000217174" ixz="0.001340587" iyy="0.017786991" iyz="-0.000187749" izz="0.020774433"/>
    </inertial>
    <visual>
      <geometry>
        <mesh filename="package://val_description/model/meshes/legs/foot.dae"/>
      </geometry>
      <origin rpy="0 0 0" xyz="0 0 0"/>
    </visual>
    <collision>
      <geometry>
        <box size="0.27 0.16 0.064"/>
      </geometry>
      <origin rpy="0.0 0.0 0.0" xyz="0.045 0.0 -0.056"/>
    </collision>
  </link>
  <!-- foot contact parameters copied from atlas_description in drcsim -->
  <gazebo reference="leftFoot">
    <!-- kp and kd for rubber -->
    <kp>1000000.0</kp>
    <kd>100.0</kd>
    <mu1>1.5</mu1>
    <mu2>1.5</mu2>
    <fdir1>1 0 0</fdir1>
    <maxVel>1.0</maxVel>
    <minDepth>0.00</minDepth>
  </gazebo>
  <joint name="leftHipYaw" type="revolute">
    <origin rpy="0.0 0.0 0.0" xyz="0.0 0.1016 -0.1853"/>
    <axis xyz="0 0 1"/>
    <parent link="world"/>
    <child link="leftHipYawLink"/>
    <limit effort="190" lower="-0.38" upper="1.03" velocity="5.89"/>
    <controller_gains Kd="0.0" Ki="0.0" Kp="0.0"/>
    <dynamics damping="0.1" friction="0.0"/>
  </joint>
  <gazebo reference="leftHipYaw">
    <provideFeedback>1</provideFeedback>
    <implicitSpringDamper>1</implicitSpringDamper>
  </gazebo>
  <joint name="leftHipRoll" type="revolute">
    <origin rpy="0.0 0.0 0.0" xyz="0.0 0.0 0.0"/>
    <axis xyz="1 0 0"/>
    <parent link="leftHipYawLink"/>
    <child link="leftHipRollLink"/>
    <limit effort="350" lower="-0.45" upper="0.4815" velocity="7"/>
    <controller_gains Kd="0.0" Ki="0.0" Kp="0.0"/>
    <dynamics damping="0.1" friction="0.0"/>
  </joint>
  <gazebo reference="leftHipRoll">
    <provideFeedback>1</provideFeedback>
    <implicitSpringDamper>1</implicitSpringDamper>
  </gazebo>
  <joint name="leftHipPitch" type="revolute">
    <origin rpy="0.0 0.0 0.0" xyz="0.0 0.0 -0.0609"/>
    <axis xyz="0 1 0"/>
    <parent link="leftHipRollLink"/>
    <child link="leftHipPitchLink"/>
    <limit effort="350" lower="-1.63" upper="1.549" velocity="6.11"/>
    <controller_gains Kd="0.0" Ki="0.0" Kp="0.0"/>
    <dynamics damping="0.1" friction="0.0"/>
  </joint>
  <gazebo reference="leftHipPitch">
    <provideFeedback>1</provideFeedback>
    <implicitSpringDamper>1</implicitSpringDamper>
  </gazebo>
  <joint name="leftKneePitch" type="revolute">
    <origin rpy="0.0 0.0 0.0" xyz="0.000112225 0.0361046 -0.430959"/>
    <axis xyz="0 1 0"/>
    <parent link="leftHipPitchLink"/>
    <child link="leftKneePitchLink"/>
    <limit effort="350" lower="-0.055" upper="1.95" velocity="6.11"/>
    <controller_gains Kd="0.0" Ki="0.0" Kp="0.0"/>
    <dynamics damping="0.1" friction="0.0"/>
  </joint>
  <gazebo reference="leftKneePitch">
    <provideFeedback>1</provideFeedback>
    <implicitSpringDamper>1</implicitSpringDamper>
  </gazebo>
  <joint name="leftAnklePitch" type="revolute">
    <origin rpy="0.0 0.0 0.0" xyz="-0.0102381 0.0 -0.40627"/>
    <axis xyz="0 1 0"/>
    <parent link="leftKneePitchLink"/>
    <child link="leftAnklePitchLink"/>
    <limit effort="205" lower="-0.93" upper="0.65" velocity="11"/>
    <controller_gains Kd="0.0" Ki="0.0" Kp="0.0"/>
    <dynamics damping="0.1" friction="0.0"/>
  </joint>
  <gazebo reference="leftAnklePitch">
    <provideFeedback>1</provideFeedback>
    <implicitSpringDamper>1</implicitSpringDamper>
  </gazebo>
  <joint name="leftAnkleRoll" type="revolute">
    <origin rpy="0.0 0.0 0.0" xyz="0.0 0.0 0.0"/>
    <axis xyz="1 0 0"/>
    <parent link="leftAnklePitchLink"/>
    <child link="leftFoot"/>
    <limit effort="205" lower="-0.4" upper="0.4" velocity="11"/>
    <controller_gains Kd="0.0" Ki="0.0" Kp="0.0"/>
    <dynamics damping="0.3" friction="0.0"/>
  </joint>
  <gazebo reference="leftAnkleRoll">
    <provideFeedback>1</provideFeedback>
    <implicitSpringDamper>1</implicitSpringDamper>
  </gazebo>
  <link name="leftCOP_Frame">
    <inertial>
      <mass value="0.1"/>
      <origin rpy="0 0 0" xyz="0 0 0"/>
      <inertia ixx="8.333333333333336e-05" ixy="0.0" ixz="0.0" iyy="8.333333333333336e-05" iyz="0.0" izz="0.00012500000000000003"/>
    </inertial>
  </link>
  <joint name="leftCOP_Offset" type="fixed">
    <origin rpy="0.0 0.0 0.0" xyz="0.0189 0.0 -0.0783"/>
    <axis xyz="0 0 1"/>
    <parent link="leftFoot"/>
    <child link="leftCOP_Frame"/>
  </joint>
  <gazebo reference="leftCOP_Offset">
    <implicitSpringDamper>1</implicitSpringDamper>
  </gazebo>
  <link name="leftFootSixAxis_Frame">
    <!-- Virtual Link -->
    <inertial>
      <mass value="1e-07"/>
      <origin rpy="0 0 0" xyz="0 0 0"/>
      <inertia ixx="3.3333333333333322e-22" ixy="0.0" ixz="0.0" iyy="3.3333333333333322e-22" iyz="0.0" izz="4.999999999999999e-22"/>
    </inertial>
  </link>
  <joint name="leftFootSixAxis_Offset" type="fixed">
    <origin rpy="3.14 0.0 0.0" xyz="0.0215646 0.0 -0.051054"/>
    <axis xyz="0 0 1"/>
    <parent link="leftFoot"/>
    <child link="leftFootSixAxis_Frame"/>
  </joint>
  <gazebo reference="leftFootSixAxis_Offset">
    <implicitSpringDamper>1</implicitSpringDamper>
  </gazebo>
  <gazebo reference="leftAnkleRoll">
    <sensor name="leftFootSixAxis" type="force_torque">
      <pose>0.0215646 0.0 -0.051054 3.14 0.0 0.0</pose>
      <sensor_number id="FT16594"/>
      <node id="/left_leg/ankle/left_actuator"/>
      <api name="ati_sensor_interface::ATISensorInterface"/>
      <always_on>true</always_on>
      <update_rate>500.0</update_rate>
      <force_torque>
        <frame>sensor</frame>
        <measure_direction>parent_to_child</measure_direction>
      </force_torque>
    </sensor>
  </gazebo>
  <transmission name="leftHipYawTransmission">
    <type>transmission_interface/SimpleTransmission</type>
    <joint name="leftHipYaw">
      <hardwareInterface>EffortJointInterface</hardwareInterface>
    </joint>
    <actuator name="leftHipYaw">
      <node name="/pelvis/left_leg_j1"/>
      <mechanicalReduction>1</mechanicalReduction>
      <api name="robot_hardware_interface/TurbodriverAPI"/>
    </actuator>
  </transmission>
  <transmission name="leftHipRollTransmission">
    <type>transmission_interface/SimpleTransmission</type>
    <joint name="leftHipRoll">
      <hardwareInterface>EffortJointInterface</hardwareInterface>
    </joint>
    <actuator name="leftHipRoll">
      <node name="/left_leg/j2"/>
      <mechanicalReduction>1</mechanicalReduction>
      <api name="robot_hardware_interface/TurbodriverAPI"/>
    </actuator>
  </transmission>
  <transmission name="leftHipPitchTransmission">
    <type>transmission_interface/SimpleTransmission</type>
    <joint name="leftHipPitch">
      <hardwareInterface>EffortJointInterface</hardwareInterface>
    </joint>
    <actuator name="leftHipPitch">
      <node name="/left_leg/j3"/>
      <mechanicalReduction>1</mechanicalReduction>
      <api name="robot_hardware_interface/TurbodriverAPI"/>
    </actuator>
  </transmission>
  <transmission name="leftKneePitchTransmission">
    <type>transmission_interface/SimpleTransmission</type>
    <joint name="leftKneePitch">
      <hardwareInterface>EffortJointInterface</hardwareInterface>
    </joint>
    <actuator name="leftKneePitch">
      <node name="/left_leg/j4"/>
      <mechanicalReduction>1</mechanicalReduction>
      <api name="robot_hardware_interface/TurbodriverAPI"/>
    </actuator>
  </transmission>
  <transmission name="leftAnkleTransmission">
    <type>robot_transmission_interface::AnklePushrodTransmissionLoader</type>
    <joint name="leftAnklePitch">
      <role>pitch</role>
      <hardwareInterface>EffortJointInterface</hardwareInterface>
    </joint>
    <joint name="leftAnkleRoll">
      <role>roll</role>
      <hardwareInterface>EffortJointInterface</hardwareInterface>
    </joint>
    <actuator name="leftAnkleRightActuator">
      <node name="/left_leg/ankle/right_actuator"/>
      <role>right</role>
      <mechanicalReduction>1</mechanicalReduction>
      <api name="robot_hardware_interface/TurbodriverAPI_linear_futek"/>
    </actuator>
    <actuator name="leftAnkleLeftActuator">
      <node name="/left_leg/ankle/left_actuator"/>
      <role>left</role>
      <mechanicalReduction>1</mechanicalReduction>
      <api name="robot_hardware_interface/TurbodriverAPI_linear_futek"/>
    </actuator>
  </transmission>
</robot>
